<!-- passiveWalker_model.xml -->

<mujoco model="PassiveWalker_YunusEmreDanabas">

  <option timestep="0.001" gravity="0  0 -9.81"/>

 <!-- Gravity for the ramp
  <option timestep="0.001" gravity="1.94894614  0.         -9.61445313"/>
 -->

  <asset>
    <!-- Textures and materials -->
    <texture name="ground_texture" type="2d" builtin="checker" width="512" height="512"
             rgb1="0.8 0.8 0.8" rgb2="0.2 0.3 0.3"/>
    <material name="ground_material" texture="ground_texture" texrepeat="20 20" reflectance="0.2"/>
    <material name="torso_material" rgba="0.6 0.3 0.3 1"/>
    <material name="leg_material" rgba="0.3 0.6 0.3 1"/>
    <material name="feet_material" rgba="0.8 0.4 0.2 1"/>
  </asset>

  <worldbody>
    <!-- Ground plane -->
    <geom name="ground" type="plane" size="40 40 0.1" material="ground_material"/>

    <!-- Light source -->
    <light pos="10 0 30" dir="0 0 -1" diffuse="1 1 1" specular="0.5 0.5 0.5"/>
    <light pos="30 0 30" dir="0 0 -1" diffuse="1 1 1" specular="0.5 0.5 0.5"/>


    <!-- Torso with constrained movement -->
    <body name="torso" pos="0 0 1.3" euler="0 0 0">
      <!-- Allow forward/backward sliding and vertical movement -->
      <joint name="slide_x" type="slide" axis="1 0 0"/>
      <joint name="slide_z" type="slide" axis="0 0 1"/>
      <!-- Allow yaw rotation only -->
      <joint name="yaw" type="hinge" axis="0 1 0"/>
      <geom name="torso_geom" type="sphere" size="0.1" mass="5" material="torso_material"/>


      <!-- Left Leg -->
      <body name="left_leg"  pos="0 -0.125 -0.5" euler="0 0 0">
      <joint name="left_leg_lock"
         type="hinge"
         axis="1 0 0"
         limited="true"
         range="0 0.01"/>

        <!-- Left Thigh -->
        <geom name="left_thigh" type="capsule" size=".05 .5" mass="1" material="leg_material"/>
          <!-- Knee joint -->
          <body name="left_foot" pos="0 0 -0.75">
            <joint name="left_knee" type="slide" pos="0 0 0.25" axis = "0 0 -1" range="-0.30 0.30"/>
            <!-- Shin geometry -->
            <geom name="left_shin_geom" type="capsule" fromto="0 0 0 0 0 0.5"
                  size="0.02" material="leg_material" mass="0.0"/>
            <!-- Foot geometry -->
            <geom name="left_foot_geom" type="sphere" size=".05" material="feet_material" mass="0.1" /> 
          </body>
      </body>
      
      <!-- Right Leg -->
      <body name="right_leg" pos="0 0.125 -0.5" euler="0 0 0">
        <!-- Hip joint -->
        <joint name="hip" type="hinge" pos="0 0 0.5" axis="0 -1 0" />
        <!-- Thigh geometry -->
        <geom name="right_thigh" type="capsule" size=".05 .5" mass="1" material="leg_material"/>
        <!-- Knee joint -->
        <body name="right_foot" pos="0 0 -0.75">
          <joint name="right_knee" type="slide" axis="0 0 -1" range="-0.30 0.30"/>
          <!-- Shin geometry -->
          <geom name="right_shin_geom" type="capsule" fromto="0 0 0 0 0 0.5"
                size="0.02" material="leg_material" mass="0.0"/>
          <!-- Foot geometry -->
          <geom name="right_foot_geom" type="sphere" size=".05"  material="feet_material" mass="0.1" /> 
        </body>
      </body>

    </body>
  </worldbody>


<actuator>
  <!-- Hip: kp = 5, kv = 1 -->
  <general name="hip_act" joint="hip"
           gaintype="fixed"   gainprm="5"
           biastype="affine"  biasprm="0 -5 -1"
           ctrllimited="true" ctrlrange="-0.5 0.5"/>

  <!-- Left knee: kp = 1000, kv = 100 -->
  <general name="left_knee_act" joint="left_knee"
           gaintype="fixed"   gainprm="1000"
           biastype="affine"  biasprm="0 -1000 -100"
           ctrllimited="true" ctrlrange="-0.3 0.3"/>

  <!-- Right knee: kp = 1000, kv = 100 -->
  <general name="right_knee_act" joint="right_knee"
           gaintype="fixed"   gainprm="1000"
           biastype="affine"  biasprm="0 -1000 -100"
           ctrllimited="true" ctrlrange="-0.3 0.3"/>

  </actuator>

</mujoco>
